File: XRD/Task 3/powder.csv
[Measurement conditions]
Sample identification,
Comment,
Anode material,Cu
K-Alpha1 wavelength,1.5405980
K-Alpha2 wavelength,1.5444260
Ratio K-Alpha2/K-Alpha1,0.500
Monochromator used,NO
Generator voltage, 10
Tube current, 10
File date and time,21-May-2024 14:35
Unit cell,
h k l, 0 0 0
Scan axis,2Theta-Omega
Scan range,10.0100,89.9900
Scan step size,0.0200000
Omega offset,0.0000
No. of points, 3999
Scan type,CONTINUOUS
Time per step,0.50
[Scan points]
Angle,Intensity
10.0200,12.0
10.0800,12.0
10.1400,16.0
10.2000,9.0
10.2600,11.0
10.3200,13.0
10.3800,10.0
10.4400,13.0
10.5000,10.0
10.5600,16.0
10.6200,12.0
10.6800,18.0
10.7400,13.0
10.8000,16.0
10.8600,15.0
10.9200,14.0
10.9800,10.0
11.0400,16.0
11.1000,12.0
11.1600,15.0
11.2200,8.0
11.2800,12.0
11.3400,14.0
11.4000,10.0
11.4600,19.0
11.5200,11.0
11.5800,9.0
11.6400,14.0
11.7000,11.0
11.7600,7.0
11.8200,13.0
11.8800,11.0
11.9400,12.0
12.0000,10.0
12.0600,15.0
12.1200,10.0
12.1800,10.0
12.2400,12.0
12.3000,10.0
12.3600,10.0
12.4200,14.0
12.4800,11.0
12.5400,12.0
12.6000,8.0
12.6600,14.0
12.7200,13.0
12.7800,16.0
12.8400,8.0
12.9000,6.0
12.9600,8.0
13.0200,9.0
13.0800,13.0
13.1400,9.0
13.2000,10.0
13.2600,15.0
13.3200,10.0
13.3800,9.0
13.4400,15.0
13.5000,9.0
13.5600,17.0
13.6200,7.0
13.6800,13.0
13.7400,11.0
13.8000,14.0
13.8600,6.0
13.9200,6.0
13.9800,6.0
14.0400,9.0
14.1000,11.0
14.1600,12.0
14.2200,9.0
14.2800,6.0
14.3400,7.0
14.4000,12.0
14.4600,9.0
14.5200,10.0
14.5800,10.0
14.6400,9.0
14.7000,11.0
14.7600,12.0
14.8200,11.0
14.8800,7.0
14.9400,9.0
15.0000,4.0
15.0600,8.0
15.1200,16.0
15.1800,11.0
15.2400,11.0
15.3000,12.0
15.3600,8.0
15.4200,7.0
15.4800,10.0
15.5400,4.0
15.6000,5.0
15.6600,5.0
15.7200,10.0
15.7800,4.0
15.8400,5.0
15.9000,15.0
15.9600,10.0
16.0200,5.0
16.0800,9.0
16.1400,4.0
16.2000,8.0
16.2600,5.0
16.3200,5.0
16.3800,9.0
16.4400,9.0
16.5000,8.0
16.5600,5.0
16.6200,8.0
16.6800,6.0
16.7400,5.0
16.8000,4.0
16.8600,8.0
16.9200,5.0
16.9800,7.0
17.0400,15.0
17.1000,5.0
17.1600,7.0
17.2200,8.0
17.2800,12.0
17.3400,8.0
17.4000,13.0
17.4600,8.0
17.5200,10.0
17.5800,14.0
17.6400,6.0
17.7000,7.0
17.7600,14.0
17.8200,15.0
17.8800,19.0
17.9400,29.0
18.0000,23.0
18.0600,28.0
18.1200,34.0
18.1800,50.0
18.2400,63.0
18.3000,51.0
18.3600,54.0
18.4200,57.0
18.4800,70.0
18.5400,61.0
18.6000,27.0
18.6600,44.0
18.7200,31.0
18.7800,30.0
18.8400,21.0
18.9000,16.0
18.9600,18.0
19.0200,9.0
19.0800,8.0
19.1400,9.0
19.2000,7.0
19.2600,6.0
19.3200,3.0
19.3800,8.0
19.4400,11.0
19.5000,5.0
19.5600,4.0
19.6200,12.0
19.6800,7.0
19.7400,8.0
19.8000,3.0
19.8600,4.0
19.9200,4.0
19.9800,7.0
20.0400,7.0
20.1000,7.0
20.1600,4.0
20.2200,3.0
20.2800,4.0
20.3400,3.0
20.4000,4.0
20.4600,5.0
20.5200,6.0
20.5800,6.0
20.6400,1.0
20.7000,3.0
20.7600,2.0
20.8200,1.0
20.8800,0.0
20.9400,3.0
21.0000,4.0
21.0600,5.0
21.1200,3.0
21.1800,5.0
21.2400,4.0
21.3000,5.0
21.3600,2.0
21.4200,4.0
21.4800,6.0
21.5400,8.0
21.6000,3.0
21.6600,5.0
21.7200,2.0
21.7800,4.0
21.8400,5.0
21.9000,5.0
21.9600,5.0
22.0200,5.0
22.0800,5.0
22.1400,3.0
22.2000,1.0
22.2600,3.0
22.3200,6.0
22.3800,6.0
22.4400,1.0
22.5000,3.0
22.5600,6.0
22.6200,7.0
22.6800,1.0
22.7400,6.0
22.8000,4.0
22.8600,3.0
22.9200,3.0
22.9800,3.0
23.0400,3.0
23.1000,2.0
23.1600,4.0
23.2200,5.0
23.2800,0.0
23.3400,6.0
23.4000,1.0
23.4600,4.0
23.5200,3.0
23.5800,4.0
23.6400,4.0
23.7000,3.0
23.7600,4.0
23.8200,5.0
23.8800,2.0
23.9400,1.0
24.0000,0.0
24.0600,5.0
24.1200,3.0
24.1800,1.0
24.2400,5.0
24.3000,1.0
24.3600,1.0
24.4200,3.0
24.4800,1.0
24.5400,4.0
24.6000,3.0
24.6600,4.0
24.7200,3.0
24.7800,6.0
24.8400,5.0
24.9000,3.0
24.9600,3.0
25.0200,0.0
25.0800,4.0
25.1400,1.0
25.2000,5.0
25.2600,7.0
25.3200,6.0
25.3800,4.0
25.4400,3.0
25.5000,3.0
25.5600,2.0
25.6200,3.0
25.6800,3.0
25.7400,2.0
25.8000,5.0
25.8600,3.0
25.9200,2.0
25.9800,5.0
26.0400,1.0
26.1000,1.0
26.1600,5.0
26.2200,2.0
26.2800,3.0
26.3400,0.0
26.4000,2.0
26.4600,0.0
26.5200,1.0
26.5800,4.0
26.6400,4.0
26.7000,3.0
26.7600,2.0
26.8200,9.0
26.8800,4.0
26.9400,3.0
27.0000,1.0
27.0600,6.0
27.1200,1.0
27.1800,1.0
27.2400,3.0
27.3000,3.0
27.3600,2.0
27.4200,1.0
27.4800,2.0
27.5400,0.0
27.6000,2.0
27.6600,5.0
27.7200,3.0
27.7800,8.0
27.8400,5.0
27.9000,2.0
27.9600,7.0
28.0200,4.0
28.0800,1.0
28.1400,2.0
28.2000,9.0
28.2600,5.0
28.3200,3.0
28.3800,2.0
28.4400,4.0
28.5000,4.0
28.5600,1.0
28.6200,4.0
28.6800,2.0
28.7400,2.0
28.8000,7.0
28.8600,4.0
28.9200,3.0
28.9800,2.0
29.0400,1.0
29.1000,2.0
29.1600,8.0
29.2200,4.0
29.2800,4.0
29.3400,3.0
29.4000,2.0
29.4600,2.0
29.5200,4.0
29.5800,1.0
29.6400,4.0
29.7000,2.0
29.7600,3.0
29.8200,1.0
29.8800,2.0
29.9400,3.0
30.0000,3.0
30.0600,0.0
30.1200,3.0
30.1800,2.0
30.2400,1.0
30.3000,2.0
30.3600,2.0
30.4200,5.0
30.4800,6.0
30.5400,4.0
30.6000,10.0
30.6600,5.0
30.7200,11.0
30.7800,8.0
30.8400,2.0
30.9000,8.0
30.9600,1.0
31.0200,8.0
31.0800,5.0
31.1400,2.0
31.2000,2.0
31.2600,3.0
31.3200,2.0
31.3800,1.0
31.4400,5.0
31.5000,4.0
31.5600,2.0
31.6200,4.0
31.6800,3.0
31.7400,2.0
31.8000,7.0
31.8600,2.0
31.9200,6.0
31.9800,8.0
32.0400,19.0
32.1000,33.0
32.1600,25.0
32.2200,17.0
32.2800,8.0
32.3400,7.0
32.4000,5.0
32.4600,2.0
32.5200,6.0
32.5800,5.0
32.6400,6.0
32.7000,7.0
32.7600,9.0
32.8200,8.0
32.8800,6.0
32.9400,6.0
33.0000,8.0
33.0600,6.0
33.1200,4.0
33.1800,5.0
33.2400,8.0
33.3000,3.0
33.3600,2.0
33.4200,9.0
33.4800,6.0
33.5400,6.0
33.6000,7.0
33.6600,5.0
33.7200,6.0
33.7800,5.0
33.8400,7.0
33.9000,10.0
33.9600,8.0
34.0200,5.0
34.0800,12.0
34.1400,10.0
34.2000,33.0
34.2600,63.0
34.3200,117.0
34.3800,119.0
34.4400,62.0
34.5000,30.0
34.5600,10.0
34.6200,8.0
34.6800,7.0
34.7400,5.0
34.8000,4.0
34.8600,7.0
34.9200,5.0
34.9800,9.0
35.0400,6.0
35.1000,6.0
35.1600,2.0
35.2200,7.0
35.2800,2.0
35.3400,6.0
35.4000,9.0
35.4600,7.0
35.5200,1.0
35.5800,7.0
35.6400,5.0
35.7000,5.0
35.7600,11.0
35.8200,9.0
35.8800,12.0
35.9400,6.0
36.0000,7.0
36.0600,16.0
36.1200,8.0
36.1800,17.0
36.2400,18.0
36.3000,24.0
36.3600,27.0
36.4200,70.0
36.4800,121.0
36.5400,177.0
36.6000,151.0
36.6600,89.0
36.7200,31.0
36.7800,15.0
36.8400,7.0
36.9000,8.0
36.9600,15.0
37.0200,9.0
37.0800,14.0
37.1400,11.0
37.2000,19.0
37.2600,18.0
37.3200,17.0
37.3800,25.0
37.4400,21.0
37.5000,32.0
37.5600,26.0
37.6200,40.0
37.6800,40.0
37.7400,39.0
37.8000,68.0
37.8600,57.0
37.9200,43.0
37.9800,61.0
38.0400,43.0
38.1000,42.0
38.1600,40.0
38.2200,35.0
38.2800,35.0
38.3400,36.0
38.4000,27.0
38.4600,23.0
38.5200,25.0
38.5800,16.0
38.6400,20.0
38.7000,10.0
38.7600,11.0
38.8200,14.0
38.8800,9.0
38.9400,7.0
39.0000,10.0
39.0600,9.0
39.1200,8.0
39.1800,8.0
39.2400,2.0
39.3000,6.0
39.3600,2.0
39.4200,9.0
39.4800,7.0
39.5400,12.0
39.6000,5.0
39.6600,5.0
39.7200,8.0
39.7800,4.0
39.8400,7.0
39.9000,6.0
39.9600,7.0
40.0200,7.0
40.0800,3.0
40.1400,6.0
40.2000,5.0
40.2600,5.0
40.3200,2.0
40.3800,2.0
40.4400,4.0
40.5000,7.0
40.5600,4.0
40.6200,4.0
40.6800,7.0
40.7400,6.0
40.8000,7.0
40.8600,8.0
40.9200,5.0
40.9800,6.0
41.0400,6.0
41.1000,4.0
41.1600,3.0
41.2200,5.0
41.2800,4.0
41.3400,4.0
41.4000,3.0
41.4600,3.0
41.5200,2.0
41.5800,3.0
41.6400,4.0
41.7000,4.0
41.7600,4.0
41.8200,11.0
41.8800,8.0
41.9400,4.0
42.0000,8.0
42.0600,1.0
42.1200,5.0
42.1800,7.0
42.2400,8.0
42.3000,5.0
42.3600,3.0
42.4200,3.0
42.4800,2.0
42.5400,3.0
42.6000,3.0
42.6600,4.0
42.7200,3.0
42.7800,2.0
42.8400,3.0
42.9000,5.0
42.9600,3.0
43.0200,4.0
43.0800,3.0
43.1400,4.0
43.2000,6.0
43.2600,5.0
43.3200,7.0
43.3800,3.0
43.4400,4.0
43.5000,4.0
43.5600,3.0
43.6200,9.0
43.6800,5.0
43.7400,5.0
43.8000,3.0
43.8600,7.0
43.9200,4.0
43.9800,10.0
44.0400,6.0
44.1000,2.0
44.1600,5.0
44.2200,1.0
44.2800,5.0
44.3400,3.0
44.4000,4.0
44.4600,4.0
44.5200,1.0
44.5800,4.0
44.6400,4.0
44.7000,4.0
44.7600,5.0
44.8200,4.0
44.8800,3.0
44.9400,4.0
45.0000,2.0
45.0600,4.0
45.1200,3.0
45.1800,8.0
45.2400,5.0
45.3000,4.0
45.3600,6.0
45.4200,3.0
45.4800,7.0
45.5400,12.0
45.6000,3.0
45.6600,11.0
45.7200,3.0
45.7800,4.0
45.8400,6.0
45.9000,6.0
45.9600,2.0
46.0200,1.0
46.0800,6.0
46.1400,5.0
46.2000,5.0
46.2600,4.0
46.3200,2.0
46.3800,3.0
46.4400,7.0
46.5000,2.0
46.5600,7.0
46.6200,3.0
46.6800,3.0
46.7400,4.0
46.8000,2.0
46.8600,5.0
46.9200,3.0
46.9800,4.0
47.0400,4.0
47.1000,6.0
47.1600,1.0
47.2200,5.0
47.2800,7.0
47.3400,3.0
47.4000,3.0
47.4600,3.0
47.5200,8.0
47.5800,11.0
47.6400,19.0
47.7000,37.0
47.7600,39.0
47.8200,29.0
47.8800,29.0
47.9400,20.0
48.0000,8.0
48.0600,5.0
48.1200,5.0
48.1800,7.0
48.2400,4.0
48.3000,0.0
48.3600,10.0
48.4200,5.0
48.4800,3.0
48.5400,3.0
48.6000,5.0
48.6600,6.0
48.7200,6.0
48.7800,8.0
48.8400,3.0
48.9000,4.0
48.9600,4.0
49.0200,10.0
49.0800,6.0
49.1400,11.0
49.2000,9.0
49.2600,3.0
49.3200,6.0
49.3800,11.0
49.4400,6.0
49.5000,7.0
49.5600,4.0
49.6200,1.0
49.6800,7.0
49.7400,12.0
49.8000,12.0
49.8600,9.0
49.9200,9.0
49.9800,10.0
50.0400,14.0
50.1000,12.0
50.1600,13.0
50.2200,10.0
50.2800,14.0
50.3400,9.0
50.4000,13.0
50.4600,17.0
50.5200,16.0
50.5800,18.0
50.6400,13.0
50.7000,13.0
50.7600,20.0
50.8200,18.0
50.8800,22.0
50.9400,18.0
51.0000,9.0
51.0600,17.0
51.1200,14.0
51.1800,12.0
51.2400,11.0
51.3000,7.0
51.3600,13.0
51.4200,8.0
51.4800,11.0
51.5400,11.0
51.6000,8.0
51.6600,4.0
51.7200,6.0
51.7800,8.0
51.8400,2.0
51.9000,6.0
51.9600,7.0
52.0200,8.0
52.0800,8.0
52.1400,3.0
52.2000,4.0
52.2600,5.0
52.3200,6.0
52.3800,7.0
52.4400,5.0
52.5000,8.0
52.5600,4.0
52.6200,4.0
52.6800,10.0
52.7400,6.0
52.8000,3.0
52.8600,2.0
52.9200,4.0
52.9800,8.0
53.0400,3.0
53.1000,2.0
53.1600,2.0
53.2200,2.0
53.2800,3.0
53.3400,0.0
53.4000,2.0
53.4600,2.0
53.5200,2.0
53.5800,1.0
53.6400,1.0
53.7000,2.0
53.7600,2.0
53.8200,2.0
53.8800,1.0
53.9400,4.0
54.0000,4.0
54.0600,6.0
54.1200,4.0
54.1800,1.0
54.2400,2.0
54.3000,1.0
54.3600,2.0
54.4200,4.0
54.4800,6.0
54.5400,5.0
54.6000,5.0
54.6600,1.0
54.7200,6.0
54.7800,1.0
54.8400,3.0
54.9000,1.0
54.9600,0.0
55.0200,4.0
55.0800,1.0
55.1400,1.0
55.2000,3.0
55.2600,2.0
55.3200,2.0
55.3800,4.0
55.4400,4.0
55.5000,2.0
55.5600,4.0
55.6200,4.0
55.6800,4.0
55.7400,2.0
55.8000,0.0
55.8600,4.0
55.9200,3.0
55.9800,0.0
56.0400,4.0
56.1000,3.0
56.1600,4.0
56.2200,6.0
56.2800,1.0
56.3400,10.0
56.4000,4.0
56.4600,3.0
56.5200,3.0
56.5800,1.0
56.6400,3.0
56.7000,2.0
56.7600,5.0
56.8200,2.0
56.8800,4.0
56.9400,3.0
57.0000,6.0
57.0600,8.0
57.1200,4.0
57.1800,4.0
57.2400,12.0
57.3000,21.0
57.3600,15.0
57.4200,14.0
57.4800,7.0
57.5400,6.0
57.6000,1.0
57.6600,3.0
57.7200,3.0
57.7800,0.0
57.8400,6.0
57.9000,6.0
57.9600,7.0
58.0200,3.0
58.0800,4.0
58.1400,10.0
58.2000,12.0
58.2600,11.0
58.3200,15.0
58.3800,17.0
58.4400,19.0
58.5000,12.0
58.5600,22.0
58.6200,22.0
58.6800,18.0
58.7400,24.0
58.8000,20.0
58.8600,16.0
58.9200,13.0
58.9800,16.0
59.0400,8.0
59.1000,5.0
59.1600,8.0
59.2200,6.0
59.2800,4.0
59.3400,6.0
59.4000,6.0
59.4600,5.0
59.5200,1.0
59.5800,9.0
59.6400,4.0
59.7000,2.0
59.7600,2.0
59.8200,5.0
59.8800,3.0
59.9400,3.0
60.0000,3.0
60.0600,3.0
60.1200,7.0
60.1800,4.0
60.2400,3.0
60.3000,3.0
60.3600,7.0
60.4200,3.0
60.4800,4.0
60.5400,3.0
60.6000,2.0
60.6600,0.0
60.7200,5.0
60.7800,6.0
60.8400,2.0
60.9000,4.0
60.9600,4.0
61.0200,4.0
61.0800,2.0
61.1400,7.0
61.2000,2.0
61.2600,2.0
61.3200,3.0
61.3800,3.0
61.4400,8.0
61.5000,9.0
61.5600,3.0
61.6200,7.0
61.6800,10.0
61.7400,12.0
61.8000,11.0
61.8600,13.0
61.9200,8.0
61.9800,11.0
62.0400,10.0
62.1000,6.0
62.1600,6.0
62.2200,10.0
62.2800,7.0
62.3400,9.0
62.4000,10.0
62.4600,6.0
62.5200,8.0
62.5800,4.0
62.6400,9.0
62.7000,10.0
62.7600,9.0
62.8200,10.0
62.8800,17.0
62.9400,40.0
63.0000,37.0
63.0600,50.0
63.1200,27.0
63.1800,25.0
63.2400,12.0
63.3000,11.0
63.3600,6.0
63.4200,2.0
63.4800,1.0
63.5400,3.0
63.6000,1.0
63.6600,4.0
63.7200,1.0
63.7800,0.0
63.8400,4.0
63.9000,1.0
63.9600,0.0
64.0200,2.0
64.0800,3.0
64.1400,4.0
64.2000,3.0
64.2600,4.0
64.3200,2.0
64.3800,3.0
64.4400,3.0
64.5000,4.0
64.5600,3.0
64.6200,2.0
64.6800,3.0
64.7400,5.0
64.8000,1.0
64.8600,3.0
64.9200,0.0
64.9800,4.0
65.0400,3.0
65.1000,4.0
65.1600,4.0
65.2200,1.0
65.2800,2.0
65.3400,5.0
65.4000,4.0
65.4600,3.0
65.5200,5.0
65.5800,3.0
65.6400,3.0
65.7000,2.0
65.7600,3.0
65.8200,3.0
65.8800,2.0
65.9400,4.0
66.0000,3.0
66.0600,4.0
66.1200,3.0
66.1800,3.0
66.2400,2.0
66.3000,2.0
66.3600,5.0
66.4200,5.0
66.4800,3.0
66.5400,6.0
66.6000,4.0
66.6600,1.0
66.7200,1.0
66.7800,5.0
66.8400,1.0
66.9000,3.0
66.9600,3.0
67.0200,8.0
67.0800,2.0
67.1400,3.0
67.2000,5.0
67.2600,9.0
67.3200,7.0
67.3800,6.0
67.4400,5.0
67.5000,7.0
67.5600,2.0
67.6200,7.0
67.6800,5.0
67.7400,8.0
67.8000,6.0
67.8600,3.0
67.9200,14.0
67.9800,5.0
68.0400,8.0
68.1000,9.0
68.1600,3.0
68.2200,3.0
68.2800,7.0
68.3400,7.0
68.4000,12.0
68.4600,16.0
68.5200,18.0
68.5800,23.0
68.6400,30.0
68.7000,22.0
68.7600,19.0
68.8200,12.0
68.8800,8.0
68.9400,10.0
69.0000,7.0
69.0600,6.0
69.1200,3.0
69.1800,4.0
69.2400,5.0
69.3000,5.0
69.3600,9.0
69.4200,2.0
69.4800,6.0
69.5400,7.0
69.6000,0.0
69.6600,3.0
69.7200,8.0
69.7800,5.0
69.8400,7.0
69.9000,6.0
69.9600,19.0
70.0200,10.0
70.0800,8.0
70.1400,7.0
70.2000,3.0
70.2600,8.0
70.3200,3.0
70.3800,6.0
70.4400,4.0
70.5000,2.0
70.5600,2.0
70.6200,2.0
70.6800,3.0
70.7400,5.0
70.8000,5.0
70.8600,3.0
70.9200,5.0
70.9800,4.0
71.0400,1.0
71.1000,3.0
71.1600,5.0
71.2200,3.0
71.2800,3.0
71.3400,4.0
71.4000,4.0
71.4600,4.0
71.5200,7.0
71.5800,5.0
71.6400,8.0
71.7000,3.0
71.7600,6.0
71.8200,5.0
71.8800,4.0
71.9400,5.0
72.0000,5.0
72.0600,4.0
72.1200,9.0
72.1800,7.0
72.2400,11.0
72.3000,8.0
72.3600,3.0
72.4200,11.0
72.4800,5.0
72.5400,11.0
72.6000,8.0
72.6600,6.0
72.7200,8.0
72.7800,5.0
72.8400,5.0
72.9000,3.0
72.9600,3.0
73.0200,2.0
73.0800,3.0
73.1400,2.0
73.2000,3.0
73.2600,2.0
73.3200,3.0
73.3800,2.0
73.4400,2.0
73.5000,6.0
73.5600,0.0
73.6200,6.0
73.6800,3.0
73.7400,2.0
73.8000,0.0
73.8600,3.0
73.9200,1.0
73.9800,1.0
74.0400,9.0
74.1000,1.0
74.1600,4.0
74.2200,1.0
74.2800,3.0
74.3400,3.0
74.4000,3.0
74.4600,3.0
74.5200,0.0
74.5800,3.0
74.6400,2.0
74.7000,2.0
74.7600,2.0
74.8200,1.0
74.8800,0.0
74.9400,1.0
75.0000,1.0
75.0600,2.0
75.1200,3.0
75.1800,2.0
75.2400,2.0
75.3000,4.0
75.3600,0.0
75.4200,1.0
75.4800,3.0
75.5400,1.0
75.6000,1.0
75.6600,3.0
75.7200,3.0
75.7800,1.0
75.8400,2.0
75.9000,0.0
75.9600,1.0
76.0200,2.0
76.0800,4.0
76.1400,0.0
76.2000,0.0
76.2600,1.0
76.3200,1.0
76.3800,2.0
76.4400,2.0
76.5000,2.0
76.5600,4.0
76.6200,2.0
76.6800,2.0
76.7400,3.0
76.8000,2.0
76.8600,1.0
76.9200,1.0
76.9800,0.0
77.0400,0.0
77.1000,2.0
77.1600,1.0
77.2200,1.0
77.2800,3.0
77.3400,4.0
77.4000,2.0
77.4600,3.0
77.5200,1.0
77.5800,5.0
77.6400,5.0
77.7000,2.0
77.7600,6.0
77.8200,6.0
77.8800,4.0
77.9400,5.0
78.0000,2.0
78.0600,5.0
78.1200,3.0
78.1800,1.0
78.2400,4.0
78.3000,3.0
78.3600,2.0
78.4200,0.0
78.4800,4.0
78.5400,4.0
78.6000,1.0
78.6600,2.0
78.7200,5.0
78.7800,1.0
78.8400,3.0
78.9000,2.0
78.9600,2.0
79.0200,2.0
79.0800,4.0
79.1400,6.0
79.2000,0.0
79.2600,2.0
79.3200,0.0
79.3800,1.0
79.4400,1.0
79.5000,4.0
79.5600,1.0
79.6200,1.0
79.6800,1.0
79.7400,1.0
79.8000,1.0
79.8600,3.0
79.9200,3.0
79.9800,3.0
80.0400,6.0
80.1000,7.0
80.1600,6.0
80.2200,3.0
80.2800,5.0
80.3400,2.0
80.4000,4.0
80.4600,2.0
80.5200,2.0
80.5800,3.0
80.6400,2.0
80.7000,3.0
80.7600,4.0
80.8200,6.0
80.8800,3.0
80.9400,2.0
81.0000,4.0
81.0600,4.0
81.1200,5.0
81.1800,4.0
81.2400,2.0
81.3000,5.0
81.3600,3.0
81.4200,9.0
81.4800,5.0
81.5400,8.0
81.6000,12.0
81.6600,4.0
81.7200,5.0
81.7800,4.0
81.8400,7.0
81.9000,2.0
81.9600,4.0
82.0200,6.0
82.0800,5.0
82.1400,5.0
82.2000,6.0
82.2600,3.0
82.3200,0.0
82.3800,3.0
82.4400,3.0
82.5000,1.0
82.5600,1.0
82.6200,1.0
82.6800,2.0
82.7400,2.0
82.8000,2.0
82.8600,3.0
82.9200,4.0
82.9800,1.0
83.0400,2.0
83.1000,3.0
83.1600,6.0
83.2200,1.0
83.2800,3.0
83.3400,2.0
83.4000,1.0
83.4600,0.0
83.5200,3.0
83.5800,1.0
83.6400,3.0
83.7000,2.0
83.7600,1.0
83.8200,3.0
83.8800,1.0
83.9400,1.0
84.0000,3.0
84.0600,2.0
84.1200,2.0
84.1800,2.0
84.2400,1.0
84.3000,2.0
84.3600,2.0
84.4200,1.0
84.4800,2.0
84.5400,2.0
84.6000,2.0
84.6600,1.0
84.7200,1.0
84.7800,2.0
84.8400,1.0
84.9000,2.0
84.9600,2.0
85.0200,2.0
85.0800,0.0
85.1400,3.0
85.2000,1.0
85.2600,2.0
85.3200,1.0
85.3800,2.0
85.4400,1.0
85.5000,2.0
85.5600,3.0
85.6200,1.0
85.6800,0.0
85.7400,0.0
85.8000,4.0
85.8600,1.0
85.9200,1.0
85.9800,4.0
86.0400,2.0
86.1000,1.0
86.1600,5.0
86.2200,3.0
86.2800,1.0
86.3400,1.0
86.4000,2.0
86.4600,2.0
86.5200,3.0
86.5800,3.0
86.6400,1.0
86.7000,3.0
86.7600,1.0
86.8200,0.0
86.8800,1.0
86.9400,3.0
87.0000,3.0
87.0600,0.0
87.1200,1.0
87.1800,2.0
87.2400,2.0
87.3000,4.0
87.3600,4.0
87.4200,3.0
87.4800,3.0
87.5400,0.0
87.6000,0.0
87.6600,3.0
87.7200,1.0
87.7800,7.0
87.8400,0.0
87.9000,1.0
87.9600,4.0
88.0200,1.0
88.0800,2.0
88.1400,3.0
88.2000,3.0
88.2600,4.0
88.3200,3.0
88.3800,0.0
88.4400,1.0
88.5000,1.0
88.5600,4.0
88.6200,1.0
88.6800,3.0
88.7400,2.0
88.8000,1.0
88.8600,3.0
88.9200,1.0
88.9800,3.0
89.0400,2.0
89.1000,4.0
89.1600,0.0
89.2200,2.0
89.2800,5.0
89.3400,4.0
89.4000,3.0
89.4600,0.0
89.5200,2.0
89.5800,1.0
89.6400,1.0
89.7000,3.0
89.7600,4.0
89.8200,4.0
89.8800,4.0
89.9400,2.0
89.9800,2.0