File: XRD/Task 2/ZnO-a-plane.csv
[Measurement conditions]
Sample identification,
Comment,
Anode material,Cu
K-Alpha1 wavelength,1.5405980
K-Alpha2 wavelength,1.5444260
Ratio K-Alpha2/K-Alpha1,0.500
Monochromator used,NO
Generator voltage, 10
Tube current, 10
File date and time,21-May-2024 11:29
Unit cell,
h k l, 0 0 0
Scan axis,2Theta-Omega
Scan range,30.0100,129.9900
Scan step size,0.0200000
Omega offset,0.0000
No. of points, 4999
Scan type,CONTINUOUS
Time per step,0.50
[Scan points]
Angle,Intensity
30.0200,6.0
30.1000,3.0
30.1800,2.0
30.2600,2.0
30.3400,3.0
30.4200,4.0
30.5000,5.0
30.5800,4.0
30.6600,8.0
30.7400,13.0
30.8200,12.0
30.9000,28.0
30.9800,112.0
31.0600,118.0
31.1400,19.0
31.2200,9.0
31.3000,5.0
31.3800,9.0
31.4600,11.0
31.5400,7.0
31.6200,5.0
31.7000,10.0
31.7800,7.0
31.8600,7.0
31.9400,9.0
32.0200,14.0
32.1000,11.0
32.1800,13.0
32.2600,12.0
32.3400,12.0
32.4200,19.0
32.5000,13.0
32.5800,24.0
32.6600,30.0
32.7400,32.0
32.8200,48.0
32.9000,128.0
32.9800,151.0
33.0600,58.0
33.1400,64.0
33.2200,56.0
33.3000,70.0
33.3800,84.0
33.4600,126.0
33.5400,165.0
33.6200,220.0
33.7000,271.0
33.7800,331.0
33.8600,455.0
33.9400,699.0
34.0200,1129.0
34.1000,2110.0
34.1800,4189.0
34.2600,8760.0
34.3400,38123.0
34.4200,119401.0
34.5000,82016.0
34.5800,24380.0
34.6600,2914.0
34.7400,1207.0
34.8200,770.0
34.9000,601.0
34.9800,455.0
35.0600,381.0
35.1400,289.0
35.2200,202.0
35.3000,155.0
35.3800,128.0
35.4600,83.0
35.5400,68.0
35.6200,39.0
35.7000,37.0
35.7800,29.0
35.8600,32.0
35.9400,30.0
36.0200,28.0
36.1000,36.0
36.1800,26.0
36.2600,29.0
36.3400,33.0
36.4200,21.0
36.5000,18.0
36.5800,21.0
36.6600,11.0
36.7400,11.0
36.8200,17.0
36.9000,16.0
36.9800,20.0
37.0600,14.0
37.1400,22.0
37.2200,29.0
37.3000,35.0
37.3800,48.0
37.4600,177.0
37.5400,710.0
37.6200,1169.0
37.7000,11401.0
37.7800,5525.0
37.8600,2674.0
37.9400,255.0
38.0200,142.0
38.1000,138.0
38.1800,112.0
38.2600,99.0
38.3400,83.0
38.4200,84.0
38.5000,59.0
38.5800,50.0
38.6600,50.0
38.7400,37.0
38.8200,30.0
38.9000,21.0
38.9800,21.0
39.0600,12.0
39.1400,17.0
39.2200,8.0
39.3000,10.0
39.3800,4.0
39.4600,6.0
39.5400,5.0
39.6200,10.0
39.7000,7.0
39.7800,12.0
39.8600,3.0
39.9400,5.0
40.0200,2.0
40.1000,2.0
40.1800,4.0
40.2600,4.0
40.3400,3.0
40.4200,3.0
40.5000,0.0
40.5800,2.0
40.6600,2.0
40.7400,2.0
40.8200,2.0
40.9000,3.0
40.9800,0.0
41.0600,1.0
41.1400,1.0
41.2200,5.0
41.3000,2.0
41.3800,7.0
41.4600,2.0
41.5400,1.0
41.6200,1.0
41.7000,3.0
41.7800,1.0
41.8600,2.0
41.9400,4.0
42.0200,1.0
42.1000,2.0
42.1800,1.0
42.2600,2.0
42.3400,0.0
42.4200,4.0
42.5000,1.0
42.5800,1.0
42.6600,1.0
42.7400,1.0
42.8200,1.0
42.9000,1.0
42.9800,3.0
43.0600,1.0
43.1400,3.0
43.2200,1.0
43.3000,0.0
43.3800,4.0
43.4600,2.0
43.5400,4.0
43.6200,2.0
43.7000,1.0
43.7800,3.0
43.8600,2.0
43.9400,2.0
44.0200,2.0
44.1000,2.0
44.1800,2.0
44.2600,4.0
44.3400,1.0
44.4200,3.0
44.5000,1.0
44.5800,1.0
44.6600,0.0
44.7400,0.0
44.8200,1.0
44.9000,2.0
44.9800,1.0
45.0600,1.0
45.1400,2.0
45.2200,1.0
45.3000,1.0
45.3800,1.0
45.4600,0.0
45.5400,1.0
45.6200,0.0
45.7000,2.0
45.7800,0.0
45.8600,1.0
45.9400,3.0
46.0200,0.0
46.1000,3.0
46.1800,1.0
46.2600,5.0
46.3400,1.0
46.4200,3.0
46.5000,3.0
46.5800,1.0
46.6600,1.0
46.7400,1.0
46.8200,0.0
46.9000,1.0
46.9800,1.0
47.0600,2.0
47.1400,2.0
47.2200,1.0
47.3000,1.0
47.3800,1.0
47.4600,0.0
47.5400,0.0
47.6200,0.0
47.7000,2.0
47.7800,0.0
47.8600,0.0
47.9400,2.0
48.0200,2.0
48.1000,2.0
48.1800,0.0
48.2600,0.0
48.3400,3.0
48.4200,1.0
48.5000,1.0
48.5800,1.0
48.6600,1.0
48.7400,4.0
48.8200,2.0
48.9000,1.0
48.9800,1.0
49.0600,1.0
49.1400,0.0
49.2200,0.0
49.3000,4.0
49.3800,0.0
49.4600,0.0
49.5400,1.0
49.6200,0.0
49.7000,2.0
49.7800,1.0
49.8600,2.0
49.9400,4.0
50.0200,1.0
50.1000,0.0
50.1800,3.0
50.2600,1.0
50.3400,2.0
50.4200,1.0
50.5000,1.0
50.5800,1.0
50.6600,0.0
50.7400,2.0
50.8200,1.0
50.9000,2.0
50.9800,1.0
51.0600,1.0
51.1400,0.0
51.2200,1.0
51.3000,0.0
51.3800,1.0
51.4600,1.0
51.5400,0.0
51.6200,1.0
51.7000,1.0
51.7800,1.0
51.8600,2.0
51.9400,0.0
52.0200,1.0
52.1000,0.0
52.1800,0.0
52.2600,0.0
52.3400,1.0
52.4200,2.0
52.5000,1.0
52.5800,0.0
52.6600,1.0
52.7400,1.0
52.8200,2.0
52.9000,1.0
52.9800,0.0
53.0600,0.0
53.1400,2.0
53.2200,1.0
53.3000,3.0
53.3800,0.0
53.4600,0.0
53.5400,2.0
53.6200,1.0
53.7000,0.0
53.7800,1.0
53.8600,1.0
53.9400,1.0
54.0200,0.0
54.1000,0.0
54.1800,0.0
54.2600,3.0
54.3400,2.0
54.4200,1.0
54.5000,1.0
54.5800,3.0
54.6600,2.0
54.7400,1.0
54.8200,1.0
54.9000,1.0
54.9800,0.0
55.0600,2.0
55.1400,0.0
55.2200,0.0
55.3000,3.0
55.3800,1.0
55.4600,1.0
55.5400,0.0
55.6200,1.0
55.7000,1.0
55.7800,0.0
55.8600,0.0
55.9400,2.0
56.0200,1.0
56.1000,2.0
56.1800,6.0
56.2600,1.0
56.3400,1.0
56.4200,0.0
56.5000,1.0
56.5800,0.0
56.6600,2.0
56.7400,2.0
56.8200,1.0
56.9000,0.0
56.9800,2.0
57.0600,0.0
57.1400,0.0
57.2200,1.0
57.3000,0.0
57.3800,0.0
57.4600,0.0
57.5400,1.0
57.6200,1.0
57.7000,1.0
57.7800,2.0
57.8600,1.0
57.9400,0.0
58.0200,0.0
58.1000,0.0
58.1800,1.0
58.2600,1.0
58.3400,1.0
58.4200,0.0
58.5000,1.0
58.5800,2.0
58.6600,0.0
58.7400,3.0
58.8200,0.0
58.9000,3.0
58.9800,1.0
59.0600,3.0
59.1400,0.0
59.2200,0.0
59.3000,2.0
59.3800,2.0
59.4600,2.0
59.5400,3.0
59.6200,2.0
59.7000,1.0
59.7800,0.0
59.8600,3.0
59.9400,1.0
60.0200,0.0
60.1000,0.0
60.1800,0.0
60.2600,1.0
60.3400,0.0
60.4200,1.0
60.5000,0.0
60.5800,1.0
60.6600,3.0
60.7400,1.0
60.8200,1.0
60.9000,1.0
60.9800,1.0
61.0600,1.0
61.1400,3.0
61.2200,2.0
61.3000,2.0
61.3800,0.0
61.4600,2.0
61.5400,2.0
61.6200,1.0
61.7000,3.0
61.7800,0.0
61.8600,0.0
61.9400,1.0
62.0200,0.0
62.1000,0.0
62.1800,0.0
62.2600,1.0
62.3400,2.0
62.4200,2.0
62.5000,0.0
62.5800,1.0
62.6600,0.0
62.7400,1.0
62.8200,2.0
62.9000,2.0
62.9800,1.0
63.0600,0.0
63.1400,0.0
63.2200,0.0
63.3000,2.0
63.3800,1.0
63.4600,2.0
63.5400,1.0
63.6200,0.0
63.7000,0.0
63.7800,1.0
63.8600,0.0
63.9400,0.0
64.0200,0.0
64.1000,0.0
64.1800,3.0
64.2600,1.0
64.3400,1.0
64.4200,1.0
64.5000,0.0
64.5800,3.0
64.6600,5.0
64.7400,2.0
64.8200,1.0
64.9000,2.0
64.9800,2.0
65.0600,2.0
65.1400,2.0
65.2200,2.0
65.3000,2.0
65.3800,2.0
65.4600,1.0
65.5400,1.0
65.6200,0.0
65.7000,2.0
65.7800,1.0
65.8600,1.0
65.9400,1.0
66.0200,0.0
66.1000,0.0
66.1800,1.0
66.2600,0.0
66.3400,1.0
66.4200,1.0
66.5000,0.0
66.5800,0.0
66.6600,0.0
66.7400,1.0
66.8200,1.0
66.9000,2.0
66.9800,1.0
67.0600,0.0
67.1400,0.0
67.2200,0.0
67.3000,1.0
67.3800,1.0
67.4600,0.0
67.5400,2.0
67.6200,2.0
67.7000,1.0
67.7800,2.0
67.8600,2.0
67.9400,2.0
68.0200,0.0
68.1000,1.0
68.1800,0.0
68.2600,2.0
68.3400,3.0
68.4200,2.0
68.5000,2.0
68.5800,1.0
68.6600,3.0
68.7400,0.0
68.8200,2.0
68.9000,1.0
68.9800,2.0
69.0600,6.0
69.1400,5.0
69.2200,6.0
69.3000,4.0
69.3800,3.0
69.4600,2.0
69.5400,0.0
69.6200,3.0
69.7000,1.0
69.7800,2.0
69.8600,4.0
69.9400,1.0
70.0200,7.0
70.1000,4.0
70.1800,5.0
70.2600,5.0
70.3400,4.0
70.4200,4.0
70.5000,3.0
70.5800,5.0
70.6600,5.0
70.7400,5.0
70.8200,6.0
70.9000,8.0
70.9800,8.0
71.0600,5.0
71.1400,7.0
71.2200,20.0
71.3000,7.0
71.3800,12.0
71.4600,15.0
71.5400,20.0
71.6200,17.0
71.7000,15.0
71.7800,28.0
71.8600,47.0
71.9400,28.0
72.0200,70.0
72.1000,91.0
72.1800,146.0
72.2600,232.0
72.3400,338.0
72.4200,683.0
72.5000,1836.0
72.5800,4128.0
72.6600,3340.0
72.7400,1876.0
72.8200,2218.0
72.9000,915.0
72.9800,229.0
73.0600,107.0
73.1400,62.0
73.2200,41.0
73.3000,44.0
73.3800,31.0
73.4600,31.0
73.5400,24.0
73.6200,25.0
73.7000,24.0
73.7800,14.0
73.8600,20.0
73.9400,12.0
74.0200,12.0
74.1000,6.0
74.1800,8.0
74.2600,7.0
74.3400,6.0
74.4200,5.0
74.5000,7.0
74.5800,6.0
74.6600,5.0
74.7400,7.0
74.8200,2.0
74.9000,4.0
74.9800,3.0
75.0600,7.0
75.1400,3.0
75.2200,6.0
75.3000,0.0
75.3800,3.0
75.4600,3.0
75.5400,3.0
75.6200,2.0
75.7000,5.0
75.7800,2.0
75.8600,2.0
75.9400,2.0
76.0200,2.0
76.1000,4.0
76.1800,1.0
76.2600,2.0
76.3400,1.0
76.4200,2.0
76.5000,3.0
76.5800,3.0
76.6600,3.0
76.7400,3.0
76.8200,1.0
76.9000,2.0
76.9800,2.0
77.0600,2.0
77.1400,3.0
77.2200,0.0
77.3000,4.0
77.3800,3.0
77.4600,0.0
77.5400,1.0
77.6200,6.0
77.7000,4.0
77.7800,1.0
77.8600,3.0
77.9400,5.0
78.0200,1.0
78.1000,2.0
78.1800,2.0
78.2600,3.0
78.3400,2.0
78.4200,0.0
78.5000,4.0
78.5800,1.0
78.6600,4.0
78.7400,0.0
78.8200,2.0
78.9000,4.0
78.9800,4.0
79.0600,7.0
79.1400,6.0
79.2200,4.0
79.3000,8.0
79.3800,7.0
79.4600,6.0
79.5400,5.0
79.6200,5.0
79.7000,5.0
79.7800,11.0
79.8600,12.0
79.9400,7.0
80.0200,13.0
80.1000,10.0
80.1800,29.0
80.2600,44.0
80.3400,52.0
80.4200,86.0
80.5000,305.0
80.5800,614.0
80.6600,3724.0
80.7400,1445.0
80.8200,446.0
80.9000,2079.0
80.9800,957.0
81.0600,155.0
81.1400,92.0
81.2200,42.0
81.3000,35.0
81.3800,28.0
81.4600,46.0
81.5400,25.0
81.6200,21.0
81.7000,17.0
81.7800,21.0
81.8600,17.0
81.9400,20.0
82.0200,16.0
82.1000,21.0
82.1800,19.0
82.2600,17.0
82.3400,16.0
82.4200,18.0
82.5000,17.0
82.5800,16.0
82.6600,14.0
82.7400,6.0
82.8200,6.0
82.9000,7.0
82.9800,12.0
83.0600,6.0
83.1400,8.0
83.2200,11.0
83.3000,7.0
83.3800,9.0
83.4600,6.0
83.5400,6.0
83.6200,3.0
83.7000,6.0
83.7800,3.0
83.8600,8.0
83.9400,3.0
84.0200,4.0
84.1000,3.0
84.1800,2.0
84.2600,2.0
84.3400,4.0
84.4200,2.0
84.5000,4.0
84.5800,0.0
84.6600,1.0
84.7400,1.0
84.8200,2.0
84.9000,0.0
84.9800,1.0
85.0600,7.0
85.1400,2.0
85.2200,1.0
85.3000,0.0
85.3800,4.0
85.4600,2.0
85.5400,1.0
85.6200,1.0
85.7000,1.0
85.7800,2.0
85.8600,0.0
85.9400,0.0
86.0200,0.0
86.1000,1.0
86.1800,2.0
86.2600,3.0
86.3400,0.0
86.4200,2.0
86.5000,1.0
86.5800,0.0
86.6600,1.0
86.7400,2.0
86.8200,2.0
86.9000,0.0
86.9800,0.0
87.0600,1.0
87.1400,0.0
87.2200,1.0
87.3000,2.0
87.3800,1.0
87.4600,1.0
87.5400,1.0
87.6200,0.0
87.7000,2.0
87.7800,1.0
87.8600,0.0
87.9400,1.0
88.0200,2.0
88.1000,0.0
88.1800,4.0
88.2600,2.0
88.3400,0.0
88.4200,0.0
88.5000,2.0
88.5800,1.0
88.6600,1.0
88.7400,2.0
88.8200,0.0
88.9000,1.0
88.9800,2.0
89.0600,1.0
89.1400,0.0
89.2200,5.0
89.3000,3.0
89.3800,2.0
89.4600,3.0
89.5400,1.0
89.6200,3.0
89.7000,1.0
89.7800,4.0
89.8600,0.0
89.9400,0.0
90.0200,0.0
90.1000,1.0
90.1800,1.0
90.2600,1.0
90.3400,0.0
90.4200,2.0
90.5000,2.0
90.5800,1.0
90.6600,2.0
90.7400,1.0
90.8200,2.0
90.9000,1.0
90.9800,1.0
91.0600,0.0
91.1400,0.0
91.2200,0.0
91.3000,2.0
91.3800,0.0
91.4600,1.0
91.5400,1.0
91.6200,1.0
91.7000,0.0
91.7800,2.0
91.8600,1.0
91.9400,1.0
92.0200,0.0
92.1000,2.0
92.1800,0.0
92.2600,1.0
92.3400,1.0
92.4200,1.0
92.5000,2.0
92.5800,1.0
92.6600,1.0
92.7400,4.0
92.8200,2.0
92.9000,2.0
92.9800,4.0
93.0600,0.0
93.1400,0.0
93.2200,1.0
93.3000,2.0
93.3800,1.0
93.4600,1.0
93.5400,1.0
93.6200,0.0
93.7000,1.0
93.7800,0.0
93.8600,0.0
93.9400,1.0
94.0200,2.0
94.1000,0.0
94.1800,3.0
94.2600,1.0
94.3400,2.0
94.4200,1.0
94.5000,2.0
94.5800,1.0
94.6600,0.0
94.7400,1.0
94.8200,1.0
94.9000,0.0
94.9800,1.0
95.0600,1.0
95.1400,3.0
95.2200,1.0
95.3000,0.0
95.3800,1.0
95.4600,0.0
95.5400,1.0
95.6200,1.0
95.7000,3.0
95.7800,2.0
95.8600,1.0
95.9400,0.0
96.0200,1.0
96.1000,5.0
96.1800,0.0
96.2600,1.0
96.3400,4.0
96.4200,2.0
96.5000,1.0
96.5800,0.0
96.6600,1.0
96.7400,4.0
96.8200,0.0
96.9000,0.0
96.9800,1.0
97.0600,0.0
97.1400,0.0
97.2200,2.0
97.3000,1.0
97.3800,1.0
97.4600,1.0
97.5400,0.0
97.6200,0.0
97.7000,0.0
97.7800,0.0
97.8600,3.0
97.9400,0.0
98.0200,1.0
98.1000,1.0
98.1800,1.0
98.2600,3.0
98.3400,1.0
98.4200,2.0
98.5000,1.0
98.5800,0.0
98.6600,0.0
98.7400,0.0
98.8200,0.0
98.9000,1.0
98.9800,1.0
99.0600,1.0
99.1400,4.0
99.2200,1.0
99.3000,1.0
99.3800,1.0
99.4600,1.0
99.5400,2.0
99.6200,0.0
99.7000,0.0
99.7800,2.0
99.8600,1.0
99.9400,1.0
100.0200,1.0
100.1000,1.0
100.1800,1.0
100.2600,0.0
100.3400,0.0
100.4200,0.0
100.5000,2.0
100.5800,1.0
100.6600,1.0
100.7400,1.0
100.8200,0.0
100.9000,0.0
100.9800,0.0
101.0600,1.0
101.1400,0.0
101.2200,2.0
101.3000,0.0
101.3800,2.0
101.4600,1.0
101.5400,2.0
101.6200,2.0
101.7000,0.0
101.7800,2.0
101.8600,0.0
101.9400,0.0
102.0200,1.0
102.1000,1.0
102.1800,2.0
102.2600,1.0
102.3400,0.0
102.4200,1.0
102.5000,2.0
102.5800,5.0
102.6600,1.0
102.7400,3.0
102.8200,0.0
102.9000,0.0
102.9800,1.0
103.0600,3.0
103.1400,0.0
103.2200,0.0
103.3000,1.0
103.3800,1.0
103.4600,1.0
103.5400,2.0
103.6200,1.0
103.7000,0.0
103.7800,2.0
103.8600,0.0
103.9400,1.0
104.0200,0.0
104.1000,0.0
104.1800,2.0
104.2600,2.0
104.3400,0.0
104.4200,2.0
104.5000,2.0
104.5800,2.0
104.6600,2.0
104.7400,0.0
104.8200,2.0
104.9000,0.0
104.9800,1.0
105.0600,1.0
105.1400,1.0
105.2200,1.0
105.3000,2.0
105.3800,2.0
105.4600,1.0
105.5400,1.0
105.6200,1.0
105.7000,2.0
105.7800,1.0
105.8600,1.0
105.9400,1.0
106.0200,0.0
106.1000,2.0
106.1800,0.0
106.2600,1.0
106.3400,1.0
106.4200,1.0
106.5000,1.0
106.5800,1.0
106.6600,3.0
106.7400,0.0
106.8200,3.0
106.9000,3.0
106.9800,1.0
107.0600,1.0
107.1400,0.0
107.2200,2.0
107.3000,0.0
107.3800,0.0
107.4600,1.0
107.5400,2.0
107.6200,0.0
107.7000,1.0
107.7800,1.0
107.8600,2.0
107.9400,0.0
108.0200,1.0
108.1000,0.0
108.1800,1.0
108.2600,2.0
108.3400,1.0
108.4200,1.0
108.5000,0.0
108.5800,1.0
108.6600,2.0
108.7400,1.0
108.8200,0.0
108.9000,2.0
108.9800,1.0
109.0600,2.0
109.1400,2.0
109.2200,1.0
109.3000,4.0
109.3800,1.0
109.4600,0.0
109.5400,3.0
109.6200,2.0
109.7000,1.0
109.7800,1.0
109.8600,2.0
109.9400,1.0
110.0200,2.0
110.1000,2.0
110.1800,0.0
110.2600,1.0
110.3400,2.0
110.4200,1.0
110.5000,1.0
110.5800,1.0
110.6600,2.0
110.7400,1.0
110.8200,2.0
110.9000,2.0
110.9800,4.0
111.0600,0.0
111.1400,1.0
111.2200,1.0
111.3000,1.0
111.3800,1.0
111.4600,0.0
111.5400,0.0
111.6200,3.0
111.7000,1.0
111.7800,1.0
111.8600,0.0
111.9400,3.0
112.0200,0.0
112.1000,1.0
112.1800,2.0
112.2600,2.0
112.3400,2.0
112.4200,1.0
112.5000,1.0
112.5800,2.0
112.6600,1.0
112.7400,1.0
112.8200,0.0
112.9000,0.0
112.9800,2.0
113.0600,0.0
113.1400,0.0
113.2200,1.0
113.3000,1.0
113.3800,1.0
113.4600,1.0
113.5400,2.0
113.6200,1.0
113.7000,2.0
113.7800,2.0
113.8600,1.0
113.9400,0.0
114.0200,1.0
114.1000,2.0
114.1800,2.0
114.2600,1.0
114.3400,0.0
114.4200,2.0
114.5000,0.0
114.5800,2.0
114.6600,1.0
114.7400,3.0
114.8200,1.0
114.9000,2.0
114.9800,1.0
115.0600,0.0
115.1400,3.0
115.2200,0.0
115.3000,1.0
115.3800,2.0
115.4600,1.0
115.5400,2.0
115.6200,1.0
115.7000,0.0
115.7800,2.0
115.8600,0.0
115.9400,0.0
116.0200,1.0
116.1000,1.0
116.1800,0.0
116.2600,6.0
116.3400,1.0
116.4200,1.0
116.5000,0.0
116.5800,2.0
116.6600,1.0
116.7400,2.0
116.8200,1.0
116.9000,0.0
116.9800,0.0
117.0600,3.0
117.1400,1.0
117.2200,1.0
117.3000,1.0
117.3800,2.0
117.4600,2.0
117.5400,1.0
117.6200,0.0
117.7000,1.0
117.7800,1.0
117.8600,2.0
117.9400,7.0
118.0200,1.0
118.1000,3.0
118.1800,1.0
118.2600,1.0
118.3400,2.0
118.4200,1.0
118.5000,1.0
118.5800,1.0
118.6600,1.0
118.7400,2.0
118.8200,0.0
118.9000,1.0
118.9800,2.0
119.0600,2.0
119.1400,1.0
119.2200,1.0
119.3000,2.0
119.3800,2.0
119.4600,3.0
119.5400,1.0
119.6200,4.0
119.7000,1.0
119.7800,2.0
119.8600,0.0
119.9400,0.0
120.0200,2.0
120.1000,1.0
120.1800,1.0
120.2600,5.0
120.3400,0.0
120.4200,2.0
120.5000,5.0
120.5800,3.0
120.6600,2.0
120.7400,1.0
120.8200,3.0
120.9000,2.0
120.9800,2.0
121.0600,3.0
121.1400,3.0
121.2200,2.0
121.3000,3.0
121.3800,2.0
121.4600,2.0
121.5400,4.0
121.6200,3.0
121.7000,2.0
121.7800,4.0
121.8600,1.0
121.9400,4.0
122.0200,3.0
122.1000,2.0
122.1800,5.0
122.2600,3.0
122.3400,4.0
122.4200,3.0
122.5000,4.0
122.5800,7.0
122.6600,8.0
122.7400,18.0
122.8200,26.0
122.9000,13.0
122.9800,4.0
123.0600,10.0
123.1400,3.0
123.2200,8.0
123.3000,10.0
123.3800,12.0
123.4600,11.0
123.5400,14.0
123.6200,6.0
123.7000,12.0
123.7800,7.0
123.8600,15.0
123.9400,18.0
124.0200,25.0
124.1000,31.0
124.1800,37.0
124.2600,42.0
124.3400,41.0
124.4200,45.0
124.5000,49.0
124.5800,61.0
124.6600,70.0
124.7400,97.0
124.8200,137.0
124.9000,182.0
124.9800,302.0
125.0600,436.0
125.1400,708.0
125.2200,1067.0
125.3000,1133.0
125.3800,871.0
125.4600,511.0
125.5400,397.0
125.6200,352.0
125.7000,421.0
125.7800,555.0
125.8600,628.0
125.9400,425.0
126.0200,258.0
126.1000,140.0
126.1800,76.0
126.2600,59.0
126.3400,47.0
126.4200,32.0
126.5000,24.0
126.5800,18.0
126.6600,13.0
126.7400,18.0
126.8200,13.0
126.9000,11.0
126.9800,9.0
127.0600,9.0
127.1400,15.0
127.2200,18.0
127.3000,11.0
127.3800,9.0
127.4600,6.0
127.5400,11.0
127.6200,4.0
127.7000,4.0
127.7800,7.0
127.8600,7.0
127.9400,4.0
128.0200,5.0
128.1000,5.0
128.1800,6.0
128.2600,11.0
128.3400,7.0
128.4200,6.0
128.5000,11.0
128.5800,10.0
128.6600,13.0
128.7400,3.0
128.8200,2.0
128.9000,5.0
128.9800,5.0
129.0600,3.0
129.1400,5.0
129.2200,4.0
129.3000,9.0
129.3800,5.0
129.4600,4.0
129.5400,3.0
129.6200,5.0
129.7000,1.0
129.7800,6.0
129.8600,6.0
129.9400,6.0
129.9800,9.0